Wed Jul 11 17:07:08 BRT 2018 Thread[main,5,main] Cleanup action starting
java.sql.SQLException: Banco de dados 'sample' não encontrado.
	at org.apache.derby.impl.jdbc.SQLExceptionFactory40.getSQLException(Unknown Source)
	at org.apache.derby.impl.jdbc.Util.newEmbedSQLException(Unknown Source)
	at org.apache.derby.impl.jdbc.Util.newEmbedSQLException(Unknown Source)
	at org.apache.derby.impl.jdbc.Util.generateCsSQLException(Unknown Source)
	at org.apache.derby.impl.jdbc.EmbedConnection.newSQLException(Unknown Source)
	at org.apache.derby.impl.jdbc.EmbedConnection.handleDBNotFound(Unknown Source)
	at org.apache.derby.impl.jdbc.EmbedConnection.<init>(Unknown Source)
	at org.apache.derby.impl.jdbc.EmbedConnection40.<init>(Unknown Source)
	at org.apache.derby.jdbc.Driver40.getNewEmbedConnection(Unknown Source)
	at org.apache.derby.jdbc.InternalDriver.connect(Unknown Source)
	at org.apache.derby.jdbc.Driver20.connect(Unknown Source)
	at org.apache.derby.jdbc.AutoloadedDriver.connect(Unknown Source)
	at java.sql.DriverManager.getConnection(DriverManager.java:664)
	at java.sql.DriverManager.getConnection(DriverManager.java:247)
	at tiago_teste_backend.conexaoBanco.getConexao(conexaoBanco.java:14)
	at tiago_teste_backend.contaCliente.adicionarCliente(contaCliente.java:19)
	at tiago_teste_backend.Main.main(Main.java:40)
Caused by: java.sql.SQLException: Banco de dados 'sample' não encontrado.
	at org.apache.derby.impl.jdbc.SQLExceptionFactory.getSQLException(Unknown Source)
	at org.apache.derby.impl.jdbc.SQLExceptionFactory40.wrapArgsForTransportAcrossDRDA(Unknown Source)
	... 17 more
============= begin nested exception, level (1) ===========
java.sql.SQLException: Banco de dados 'sample' não encontrado.
	at org.apache.derby.impl.jdbc.SQLExceptionFactory.getSQLException(Unknown Source)
	at org.apache.derby.impl.jdbc.SQLExceptionFactory40.wrapArgsForTransportAcrossDRDA(Unknown Source)
	at org.apache.derby.impl.jdbc.SQLExceptionFactory40.getSQLException(Unknown Source)
	at org.apache.derby.impl.jdbc.Util.newEmbedSQLException(Unknown Source)
	at org.apache.derby.impl.jdbc.Util.newEmbedSQLException(Unknown Source)
	at org.apache.derby.impl.jdbc.Util.generateCsSQLException(Unknown Source)
	at org.apache.derby.impl.jdbc.EmbedConnection.newSQLException(Unknown Source)
	at org.apache.derby.impl.jdbc.EmbedConnection.handleDBNotFound(Unknown Source)
	at org.apache.derby.impl.jdbc.EmbedConnection.<init>(Unknown Source)
	at org.apache.derby.impl.jdbc.EmbedConnection40.<init>(Unknown Source)
	at org.apache.derby.jdbc.Driver40.getNewEmbedConnection(Unknown Source)
	at org.apache.derby.jdbc.InternalDriver.connect(Unknown Source)
	at org.apache.derby.jdbc.Driver20.connect(Unknown Source)
	at org.apache.derby.jdbc.AutoloadedDriver.connect(Unknown Source)
	at java.sql.DriverManager.getConnection(DriverManager.java:664)
	at java.sql.DriverManager.getConnection(DriverManager.java:247)
	at tiago_teste_backend.conexaoBanco.getConexao(conexaoBanco.java:14)
	at tiago_teste_backend.contaCliente.adicionarCliente(contaCliente.java:19)
	at tiago_teste_backend.Main.main(Main.java:40)
============= end nested exception, level (1) ===========
Cleanup action completed
Wed Jul 11 17:07:13 BRT 2018 Thread[main,5,main] Cleanup action starting
java.sql.SQLException: Banco de dados 'sample' não encontrado.
	at org.apache.derby.impl.jdbc.SQLExceptionFactory40.getSQLException(Unknown Source)
	at org.apache.derby.impl.jdbc.Util.newEmbedSQLException(Unknown Source)
	at org.apache.derby.impl.jdbc.Util.newEmbedSQLException(Unknown Source)
	at org.apache.derby.impl.jdbc.Util.generateCsSQLException(Unknown Source)
	at org.apache.derby.impl.jdbc.EmbedConnection.newSQLException(Unknown Source)
	at org.apache.derby.impl.jdbc.EmbedConnection.handleDBNotFound(Unknown Source)
	at org.apache.derby.impl.jdbc.EmbedConnection.<init>(Unknown Source)
	at org.apache.derby.impl.jdbc.EmbedConnection40.<init>(Unknown Source)
	at org.apache.derby.jdbc.Driver40.getNewEmbedConnection(Unknown Source)
	at org.apache.derby.jdbc.InternalDriver.connect(Unknown Source)
	at org.apache.derby.jdbc.Driver20.connect(Unknown Source)
	at org.apache.derby.jdbc.AutoloadedDriver.connect(Unknown Source)
	at java.sql.DriverManager.getConnection(DriverManager.java:664)
	at java.sql.DriverManager.getConnection(DriverManager.java:247)
	at tiago_teste_backend.conexaoBanco.getConexao(conexaoBanco.java:14)
	at tiago_teste_backend.contaCliente.getValorCliente(contaCliente.java:32)
	at tiago_teste_backend.Main.main(Main.java:58)
Caused by: java.sql.SQLException: Banco de dados 'sample' não encontrado.
	at org.apache.derby.impl.jdbc.SQLExceptionFactory.getSQLException(Unknown Source)
	at org.apache.derby.impl.jdbc.SQLExceptionFactory40.wrapArgsForTransportAcrossDRDA(Unknown Source)
	... 17 more
============= begin nested exception, level (1) ===========
java.sql.SQLException: Banco de dados 'sample' não encontrado.
	at org.apache.derby.impl.jdbc.SQLExceptionFactory.getSQLException(Unknown Source)
	at org.apache.derby.impl.jdbc.SQLExceptionFactory40.wrapArgsForTransportAcrossDRDA(Unknown Source)
	at org.apache.derby.impl.jdbc.SQLExceptionFactory40.getSQLException(Unknown Source)
	at org.apache.derby.impl.jdbc.Util.newEmbedSQLException(Unknown Source)
	at org.apache.derby.impl.jdbc.Util.newEmbedSQLException(Unknown Source)
	at org.apache.derby.impl.jdbc.Util.generateCsSQLException(Unknown Source)
	at org.apache.derby.impl.jdbc.EmbedConnection.newSQLException(Unknown Source)
	at org.apache.derby.impl.jdbc.EmbedConnection.handleDBNotFound(Unknown Source)
	at org.apache.derby.impl.jdbc.EmbedConnection.<init>(Unknown Source)
	at org.apache.derby.impl.jdbc.EmbedConnection40.<init>(Unknown Source)
	at org.apache.derby.jdbc.Driver40.getNewEmbedConnection(Unknown Source)
	at org.apache.derby.jdbc.InternalDriver.connect(Unknown Source)
	at org.apache.derby.jdbc.Driver20.connect(Unknown Source)
	at org.apache.derby.jdbc.AutoloadedDriver.connect(Unknown Source)
	at java.sql.DriverManager.getConnection(DriverManager.java:664)
	at java.sql.DriverManager.getConnection(DriverManager.java:247)
	at tiago_teste_backend.conexaoBanco.getConexao(conexaoBanco.java:14)
	at tiago_teste_backend.contaCliente.getValorCliente(contaCliente.java:32)
	at tiago_teste_backend.Main.main(Main.java:58)
============= end nested exception, level (1) ===========
Cleanup action completed
Wed Jul 11 17:07:13 BRT 2018 Thread[main,5,main] Cleanup action starting
java.sql.SQLException: Banco de dados 'sample' não encontrado.
	at org.apache.derby.impl.jdbc.SQLExceptionFactory40.getSQLException(Unknown Source)
	at org.apache.derby.impl.jdbc.Util.newEmbedSQLException(Unknown Source)
	at org.apache.derby.impl.jdbc.Util.newEmbedSQLException(Unknown Source)
	at org.apache.derby.impl.jdbc.Util.generateCsSQLException(Unknown Source)
	at org.apache.derby.impl.jdbc.EmbedConnection.newSQLException(Unknown Source)
	at org.apache.derby.impl.jdbc.EmbedConnection.handleDBNotFound(Unknown Source)
	at org.apache.derby.impl.jdbc.EmbedConnection.<init>(Unknown Source)
	at org.apache.derby.impl.jdbc.EmbedConnection40.<init>(Unknown Source)
	at org.apache.derby.jdbc.Driver40.getNewEmbedConnection(Unknown Source)
	at org.apache.derby.jdbc.InternalDriver.connect(Unknown Source)
	at org.apache.derby.jdbc.Driver20.connect(Unknown Source)
	at org.apache.derby.jdbc.AutoloadedDriver.connect(Unknown Source)
	at java.sql.DriverManager.getConnection(DriverManager.java:664)
	at java.sql.DriverManager.getConnection(DriverManager.java:247)
	at tiago_teste_backend.conexaoBanco.getConexao(conexaoBanco.java:14)
	at tiago_teste_backend.contaCliente.getValorCliente(contaCliente.java:34)
	at tiago_teste_backend.Main.main(Main.java:58)
Caused by: java.sql.SQLException: Banco de dados 'sample' não encontrado.
	at org.apache.derby.impl.jdbc.SQLExceptionFactory.getSQLException(Unknown Source)
	at org.apache.derby.impl.jdbc.SQLExceptionFactory40.wrapArgsForTransportAcrossDRDA(Unknown Source)
	... 17 more
============= begin nested exception, level (1) ===========
java.sql.SQLException: Banco de dados 'sample' não encontrado.
	at org.apache.derby.impl.jdbc.SQLExceptionFactory.getSQLException(Unknown Source)
	at org.apache.derby.impl.jdbc.SQLExceptionFactory40.wrapArgsForTransportAcrossDRDA(Unknown Source)
	at org.apache.derby.impl.jdbc.SQLExceptionFactory40.getSQLException(Unknown Source)
	at org.apache.derby.impl.jdbc.Util.newEmbedSQLException(Unknown Source)
	at org.apache.derby.impl.jdbc.Util.newEmbedSQLException(Unknown Source)
	at org.apache.derby.impl.jdbc.Util.generateCsSQLException(Unknown Source)
	at org.apache.derby.impl.jdbc.EmbedConnection.newSQLException(Unknown Source)
	at org.apache.derby.impl.jdbc.EmbedConnection.handleDBNotFound(Unknown Source)
	at org.apache.derby.impl.jdbc.EmbedConnection.<init>(Unknown Source)
	at org.apache.derby.impl.jdbc.EmbedConnection40.<init>(Unknown Source)
	at org.apache.derby.jdbc.Driver40.getNewEmbedConnection(Unknown Source)
	at org.apache.derby.jdbc.InternalDriver.connect(Unknown Source)
	at org.apache.derby.jdbc.Driver20.connect(Unknown Source)
	at org.apache.derby.jdbc.AutoloadedDriver.connect(Unknown Source)
	at java.sql.DriverManager.getConnection(DriverManager.java:664)
	at java.sql.DriverManager.getConnection(DriverManager.java:247)
	at tiago_teste_backend.conexaoBanco.getConexao(conexaoBanco.java:14)
	at tiago_teste_backend.contaCliente.getValorCliente(contaCliente.java:34)
	at tiago_teste_backend.Main.main(Main.java:58)
============= end nested exception, level (1) ===========
Cleanup action completed
